<?xml version="1.0" encoding="utf-8"?>
<robot name="RM75-6F">
  <link name="base_link">
    <inertial>
      <origin xyz="0.00049987 5.2709E-05 0.060019" rpy="0 0 0"/>
      <mass value="1.862"/>
      <inertia ixx="0.0017232" ixy="-3.1058E-06" ixz="-3.7924E-05" iyy="0.0017051" iyz="1.3691E-06" izz="0.00090158"/>
    </inertial>
    <visual>
      <origin xyz="0 0 0" rpy="0 0 0"/>
      <geometry>
        <mesh filename="visual/base_link.obj"/>
      </geometry>
      <material name="">
        <color rgba="1 1 1 1"/>
      </material>
    </visual>
    <collision>
      <origin xyz="-0.0021500500000000006 5.000000000837668e-09 0.069250005" rpy="0 0 0"/>
      <geometry>
        <cylinder length="0.13850001" radius="0.05714995"/>
      </geometry>
    </collision>
  </link>
  <link name="link_1">
    <inertial>
      <origin xyz="0.000241 -0.013273 -0.00995" rpy="0 0 0"/>
      <mass value="1.574"/>
      <inertia ixx="0.002487573" ixy="0.000009663" ixz="-0.000007909" iyy="0.002321038" iyz="0.000179393" izz="0.001450554"/>
    </inertial>
    <visual>
      <origin xyz="0 0 0" rpy="0 0 0"/>
      <geometry>
        <mesh filename="visual/link_1.obj"/>
      </geometry>
      <material name="">
        <color rgba="1 1 1 1"/>
      </material>
    </visual>
    <collision>
      <origin xyz="5.000000000837668e-09 -0.013514125000000002 -0.030749959999999996" rpy="0 0 0"/>
      <geometry>
        <cylinder length="0.14250008" radius="0.054514115"/>
      </geometry>
    </collision>
  </link>
  <link name="link_2">
    <inertial>
      <origin xyz="-0.000357 -0.106789 0.005329" rpy="0 0 0"/>
      <mass value="1.217"/>
      <inertia ixx="0.003494121" ixy="0.000002921" ixz="-0.000005613" iyy="0.000892721" iyz="-0.000583884" izz="0.003444080"/>
    </inertial>
    <visual>
      <origin xyz="0 0 0" rpy="0 0 0"/>
      <geometry>
        <mesh filename="visual/link_2.obj"/>
      </geometry>
      <material name="">
        <color rgba="1 1 1 1"/>
      </material>
    </visual>
    <collision>
      <origin xyz="0.0 -0.055999999999999994 0.006000015000000001" rpy="-1.5707963267948966 0 0"/>
      <geometry>
        <cylinder length="0.193" radius="0.040999985"/>
      </geometry>
    </collision>
  </link>
  <link name="link_3">
    <inertial>
      <origin xyz="0.000003 -0.01398 -0.011324" rpy="0 0 0"/>
      <mass value="1.11"/>
      <inertia ixx="0.001836663" ixy="0.000002259" ixz="-0.000004216" iyy="0.001498875" iyz="0.000037167" izz="0.001062545"/>
    </inertial>
    <visual>
      <origin xyz="0 0 0" rpy="0 0 0"/>
      <geometry>
        <mesh filename="visual/link_3.obj"/>
      </geometry>
      <material name="">
        <color rgba="1 1 1 1"/>
      </material>
    </visual>
    <collision>
      <origin xyz="2.4099999999978305e-06 -0.016000085000000004 -0.034749964999999994" rpy="0 0 0"/>
      <geometry>
        <cylinder length="0.13750007" radius="0.051000015"/>
      </geometry>
    </collision>
  </link>
  <link name="link_4">
    <inertial>
      <origin xyz="-0.000005 -0.084658 0.004747" rpy="0 0 0"/>
      <mass value="0.685"/>
      <inertia ixx="0.001282444" ixy="-0.000000551" ixz="-0.000000630" iyy="0.000373013" iyz="-0.000232084" izz="0.001256177"/>
    </inertial>
    <visual>
      <origin xyz="0 0 0" rpy="0 0 0"/>
      <geometry>
        <mesh filename="visual/link_4.obj"/>
      </geometry>
      <material name="">
        <color rgba="1 1 1 1"/>
      </material>
    </visual>
    <collision>
      <origin xyz="-8.049999999995561e-07 -0.04725 0.007999949999999999" rpy="-1.5707963267948966 0 0"/>
      <geometry>
        <cylinder length="0.1625" radius="0.03700004"/>
      </geometry>
    </collision>
  </link>
  <link name="link_5">
    <inertial>
      <origin xyz="0.000078 -0.012937 -0.008781" rpy="0 0 0"/>
      <mass value="0.619"/>
      <inertia ixx="0.000627336" ixy="0.000001636" ixz="-0.000001345" iyy="0.000542455" iyz="0.000034970" izz="0.000370291"/>
    </inertial>
    <visual>
      <origin xyz="0 0 0" rpy="0 0 0"/>
      <geometry>
        <mesh filename="visual/link_5.obj"/>
      </geometry>
      <material name="">
        <color rgba="1 1 1 1"/>
      </material>
    </visual>
    <collision>
      <origin xyz="0.0 -0.01250002 -0.026499955" rpy="0 0 0"/>
      <geometry>
        <cylinder length="0.11000006999999999" radius="0.04149999"/>
      </geometry>
    </collision>
  </link>
  <link name="link_6">
    <inertial>
      <origin xyz="-0.000014 -0.078524 0.002819" rpy="0 0 0"/>
      <mass value="0.602"/>
      <inertia ixx="0.000780774" ixy="-0.000000121" ixz="-0.000000469" iyy="0.000289973" iyz="-0.000120513" izz="0.000763955"/>
    </inertial>
    <visual>
      <origin xyz="0 0 0" rpy="0 0 0"/>
      <geometry>
        <mesh filename="visual/link_6.obj"/>
      </geometry>
      <material name="">
        <color rgba="1 1 1 1"/>
      </material>
    </visual>
    <collision>
      <origin xyz="-9.049999999989622e-07 -0.043262554999999994 0.00575003" rpy="-1.5707963267948966 0 0"/>
      <geometry>
        <cylinder length="0.14347487" radius="0.034249959999999996"/>
      </geometry>
    </collision>
  </link>
  <link name="link_7">
    <inertial>
      <origin xyz="0.001094 -0.000077 -0.010119" rpy="0 0 0"/>
      <mass value="0.144"/>
      <inertia ixx="0.000044123" ixy="-0.000000064" ixz="0.0000003" iyy="0.000035078" iyz="-0.000000029" izz="0.000065445"/>
    </inertial>
    <visual>
      <origin xyz="0 0 0" rpy="0 0 0"/>
      <geometry>
        <mesh filename="visual/link_7.obj"/>
      </geometry>
      <material name="">
        <color rgba="1 1 1 1"/>
      </material>
    </visual>
    <collision>
      <origin xyz="0.0020500100000000014 4.150000000001375e-07 -0.023" rpy="0 0 0"/>
      <geometry>
        <cylinder length="0.046" radius="0.03065"/>
      </geometry>
    </collision>
  </link>
  <link name="base"/>
  <link name="tool0"/>
  <joint name="joint_1" type="revolute">
    <origin xyz="0 0 0.2405" rpy="0 0 0"/>
    <parent link="base_link"/>
    <child link="link_1"/>
    <axis xyz="0 0 1"/>
    <limit lower="-3.106" upper="3.106" effort="60" velocity="3.14"/>
  </joint>
  <joint name="joint_2" type="revolute">
    <origin xyz="0 0 0" rpy="-1.5708 0 0"/>
    <parent link="link_1"/>
    <child link="link_2"/>
    <axis xyz="0 0 1"/>
    <limit lower="-2.2689" upper="2.2689" effort="60" velocity="3.14"/>
  </joint>
  <joint name="joint_3" type="revolute">
    <origin xyz="0 -0.256 0" rpy="1.5708 0 0"/>
    <parent link="link_2"/>
    <child link="link_3"/>
    <axis xyz="0 0 1"/>
    <limit lower="-3.106" upper="3.106" effort="30" velocity="3.14"/>
  </joint>
  <joint name="joint_4" type="revolute">
    <origin xyz="0 0 0" rpy="-1.5708 0 0"/>
    <parent link="link_3"/>
    <child link="link_4"/>
    <axis xyz="0 0 1"/>
    <limit lower="-2.356" upper="2.356" effort="30" velocity="3.14"/>
  </joint>
  <joint name="joint_5" type="revolute">
    <origin xyz="0 -0.21 0" rpy="1.5708 0 0"/>
    <parent link="link_4"/>
    <child link="link_5"/>
    <axis xyz="0 0 1"/>
    <limit lower="-3.106" upper="3.106" effort="10" velocity="3.14"/>
  </joint>
  <joint name="joint_6" type="revolute">
    <origin xyz="0 0 0" rpy="-1.5708 0 0"/>
    <parent link="link_5"/>
    <child link="link_6"/>
    <axis xyz="0 0 1"/>
    <limit lower="-2.234" upper="2.234" effort="10" velocity="3.14"/>
  </joint>
  <joint name="joint_7" type="revolute">
    <origin xyz="0 -0.1612 0" rpy="1.5708 0 0"/>
    <parent link="link_6"/>
    <child link="link_7"/>
    <axis xyz="0 0 1"/>
    <limit lower="-6.2832" upper="6.2832" effort="10" velocity="3.14"/>
  </joint>
  <joint name="base_link-base" type="fixed">
    <origin xyz="0 0 0" rpy="0 0 0"/>
    <parent link="base_link"/>
    <child link="base"/>
  </joint>
  <joint name="link_7-tool0" type="fixed">
    <origin xyz="0 0 0" rpy="0 0 0"/>
    <parent link="link_7"/>
    <child link="tool0"/>
  </joint>
</robot>