<robot name="Schunk_EGK40_MB_M_B">
<!--    Note that the baselink is the start of the gripper without any mounting plate to a specific robot -->
    <link name="base_link">
        <inertial>
            <origin rpy="0 0 0" xyz="0 0 0"/>
            <mass value="1.02"/>
        </inertial>
        <visual>
            <origin rpy="0 0 0" xyz="0 0 0"/>
            <geometry>
                <mesh filename="../meshes/EGK40-MB-M-B.obj"/>
            </geometry>
            <material name="">
                <color rgba="0.1 0.1 0.1 1"/>
            </material>
        </visual>
        <collision>
            <origin rpy="0 0 0" xyz="0 0 0.0418"/>
            <geometry>
                <box size="0.117 0.068 0.0835"/>
            </geometry>
        </collision>
        <collision>
            <origin rpy="0 0 0" xyz="0.06 0 0.03"/>
            <geometry>
                <box size="0.04 0.04 0.04"/>
            </geometry>
        </collision>
    </link>

    <link name="right_finger_mount"/>
    <joint name="right_finger_mount_joint" type="prismatic">
        <parent link="base_link"/>
        <child link="right_finger_mount"/>
        <origin xyz="0.0275 0.01711 0.0835" rpy="0 0 0"/>
        <axis xyz="1 0 0"/>
        <limit lower="-0.05" upper="0" effort="10" velocity="0.1"/>
    </joint>

    <link name="left_finger_mount"/>
    <joint name="left_finger_mount_joint" type="prismatic">
        <parent link="base_link"/>
        <child link="left_finger_mount"/>
        <origin xyz="-0.0275 -0.01711 0.0835" rpy="0 0 0"/>
        <axis xyz="1 0 0"/>
        <limit lower="-0" upper="0.05" effort="10" velocity="0.1"/>
    </joint>
</robot>